Workbook

Sheet Guideline
A1: Guideline to make and understand Unit Test Case
A3: 1. Overview
A4: - In the template, Unit test cases are based on functions. Each sheet presents test cases for one function.
A5: - Cover: General information of the project and Unit Test cases
A6: - FunctionList: The list of Classes and Functions in the document. + To control that the number of Unit TC meets customer's requirement or the norm, user should fill value for 'Normal number of Test cases/KLOC'.
A7: + Click on Function link to open the related Test cases of the function. Note: You should create new Function sheet before creating the link
A8: - Test Report: provive the overview results of Functions Unit test: Test coverage, Test successful coverage (Summary, for normal/abnormal/boundary cases)
A9: Note: Should check the formula of "Sub Total" if you add more functions
A11: 2. Content in Test function sheet
A12: 2.1 Combination of test cases.
A13: - To verify that number of Unit TC meets customer's requirement or not. User has to fill number LOC of tested function and fill value of 'Normal number test cases/KLOC' item in FunctionList sheet, which is required by customer or normal value. The number of lacked TC is shown in 'Lack of test cases' item.
A14: - If the number of Unit TC does not meet the requirement, creator should explain the reasons.
... A47: - Test requirement: Brief description about requirements which are tested in this function, it is not mandatory.

Sheet Cover
B2: UNIT TEST DOCUMENT
A4: Project Name | B4: Sales Management System | E4: Creator | F4: Nam (DE200481)
A5: Project Code | B5: SALES | E5: Issue Date | F5: 46300
A6: Document Code | B6: =B5&"_"&"UnitTest"&"_"&"v1.0" -> SALES_UnitTest_v1.0 | E6: Version | F6: 1.0
A9: Record of change
A10: Effective Date | B10: Version | C10: Change Item | D10: *A,D,M | E10: Change description | F10: Reference
A11: 46300 | B11: 1.0 | C11: All | D11: A | E11: First version: unit tests for SalesService; 5 defects found and fixed | F11: Thuc hanh Unit Test - Java + JUnit 5 (handout)

Sheet Functions
E2: Function List
A4: Project Name | E4: =Cover!B4 -> Sales Management System
A5: Project Code | E5: =Cover!B5 -> SALES
A6: Normal number of Test cases/KLOC | E6: 100
A7: Test Environment Setup Description | E7: 1. OS: Windows 10/11 2. JDK 17 (Temurin) 3. Apache Maven 3.9+ 4. JUnit 5.10.2, JaCoCo 0.8.12 5. IDE: NetBeans / IntelliJ (no server or database needed)
A10: No | B10: Requirement Name | C10: Class Name | D10: Function Name | E10: Function Code(Optional) | F10: Sheet Name | G10: Description | H10: Pre-Condition
A11: 1 | B11: Subtotal | C11: SalesService | D11: calculateSubtotal(Product p) | E11: Function1 | F11: Function1 | G11: Subtotal = price x quantity; throws IllegalArgumentException if product is null | H11: new SalesService()
A12: 2 | B12: Discount | C12: SalesService | D12: calculateDiscount(double subtotal) | E12: Function2 | F12: Function2 | G12: 0% (<1,000), 5% (1,000-<5,000), 10% (5,000-<10,000), 15% (>=10,000); negative subtotal throws IAE | H12: new SalesService()
A13: 3 | B13: Shipping | C13: SalesService | D13: calculateShippingFee(double subtotal) | E13: Function3 | F13: Function3 | G13: 50 if subtotal < 2,000, otherwise 0; negative subtotal throws IAE | H13: new SalesService()
A14: 4 | B14: Total | C14: SalesService | D14: calculateTotal(Product p) | E14: Function4 | F14: Function4 | G14: Total = Subtotal - Discount + Shipping; null product throws IAE | H14: new SalesService()
A15: 5 | B15: Customer type | C15: SalesService | D15: classifyCustomer(double total) | E15: Function5 | F15: Function5 | G15: REGULAR (<1,000), SILVER (1,000-<5,000), GOLD (5,000-<10,000), VIP (>=10,000) | H15: new SalesService()

Sheet Statistics
A2: UNIT TEST REPORT
A4: Project Name | B4: =Cover!B4 -> Sales Management System | D4: Creator | F4: Nam (DE200481)
A5: Project Code | B5: =Cover!B5 -> SALES | D5: Reviewer/Approver
A6: Document Code | B6: =B5&"_"&"Test Report"&"_"&"v1.0" -> SALES_Test Report_v1.0 | D6: Issue Date | F6: 46300
A7: Notes | B7: Release 1 includes 1 class: SalesService (5 methods). Final results after fixing defects B01-B05.
A11: No | B11: Function code | C11: Passed | D11: Failed | E11: Untested | F11: N | G11: A | H11: B | I11: Total Test Cases
A12: 1 | B12: Function1 | C12: =Function1!A7 -> 5 | D12: =Function1!C7 -> 0 | E12: =Function1!F7 -> 0 | F12: =Function1!L7 -> 3 | G12: =Function1!M7 -> 1 | H12: =Function1!N7 -> 1 | I12: =Function1!O7 -> 5
A13: 2 | B13: Function2 | C13: =Function2!A7 -> 13 | D13: =Function2!C7 -> 0 | E13: =Function2!F7 -> 0 | F13: =Function2!L7 -> 4 | G13: =Function2!M7 -> 2 | H13: =Function2!N7 -> 7 | I13: =Function2!O7 -> 13
A14: 3 | B14: Function3 | C14: =Function3!A7 -> 7 | D14: =Function3!C7 -> 0 | E14: =Function3!F7 -> 0 | F14: =Function3!L7 -> 2 | G14: =Function3!M7 -> 1 | H14: =Function3!N7 -> 4 | I14: =Function3!O7 -> 7
A15: 4 | B15: Function4 | C15: =Function4!A7 -> 7 | D15: =Function4!C7 -> 0 | E15: =Function4!F7 -> 0 | F15: =Function4!L7 -> 3 | G15: =Function4!M7 -> 1 | H15: =Function4!N7 -> 3 | I15: =Function4!O7 -> 7
A16: 5 | B16: Function5 | C16: =Function5!A7 -> 10 | D16: =Function5!C7 -> 0 | E16: =Function5!F7 -> 0 | F16: =Function5!L7 -> 4 | G16: =Function5!M7 -> 0 | H16: =Function5!N7 -> 6 | I16: =Function5!O7 -> 10
B17: Sub total | C17: =SUM(C10:C16) -> 42 | D17: =SUM(D10:D16) -> 0 | E17: =SUM(E10:E16) -> 0 | F17: =SUM(F10:F16) -> 16 | G17: =SUM(G10:G16) -> 5 | H17: =SUM(H10:H16) -> 21 | I17: =SUM(I10:I16) -> 42
B19: Test coverage | D19: =(C17+D17)*100/(I17) -> 100 | E19: %
B20: Test successful coverage | D20: =C17*100/(I17) -> 100 | E20: %
B21: Normal case | D21: =F17*100/I17 -> 38.095238 | E21: %
B22: Abnormal case | D22: =G17*100/I17 -> 11.904762 | E22: %
B23: Boundary case | D23: =H17*100/I17 -> 50 | E23: %

Sheet Function1
A2: Function Code | C2: =Functions!E11 -> Function1 | F2: Function Name | L2: =Functions!D11 -> calculateSubtotal(Product p)
A3: Created By | C3: Nam (DE200481) | F3: Executed By | L3: Nam (DE200481)
A4: Lines of code | C4: 7 | F4: Lack of test cases | L4: =IF(Functions!E6<>"N/A",SUM(C4*Functions!E6/1000,-O7),"N/A") -> -4.3
A5: Test requirement | C5: Subtotal = price x quantity; throws IllegalArgumentException if product is null
A6: Passed | C6: Failed | F6: Untested | L6: N/A/B | O6: Total Test Cases
A7: =COUNTIF(F48:HQ48,"P") -> 5 | C7: =COUNTIF(F48:HQ48,"F") -> 0 | F7: =SUM(O7,-A7,-C7) -> 0 | L7: =COUNTIF(E47:HQ47,"N") -> 3 | M7: =COUNTIF(E47:HQ47,"A") -> 1 | N7: =COUNTIF(E47:HQ47,"B") -> 1 | O7: =COUNTA(F9:HT9) -> 5
F9: S01 | G9: S02 | H9: S03 | I9: S04 | J9: S05
A10: Condition | B10: Precondition
D11: SalesService object created (new SalesService()); JDK 17, JUnit 5
B12: price
D13: 500 | F13: O
D14: 100 | G14: O
D15: 1999.5 | H15: O
D16: 2000 | I16: O
B17: quantity
D18: 2 | F18: O
D19: 1 | G19: O
D20: 3 | H20: O
D21: 5 | I21: O
B22: Product
D23: null | J23: O
A24: Confirm | B24: Return
D25: 1000 | F25: O
D26: 100 | G26: O
D27: 5998.5 | H27: O
D28: 10000 | I28: O
B29: Exception
D30: IllegalArgumentException | J30: O
B31: Log message
D32: "Product cannot be null" | J32: O
A47: Result | B47: Type(N : Normal, A : Abnormal, B : Boundary) | F47: N | G47: B | H47: N | I47: N | J47: A
B48: Passed/Failed | F48: P | G48: P | H48: P | I48: P | J48: P
B49: Executed Date | F49: 46300 | G49: 46300 | H49: 46300 | I49: 46300 | J49: 46300
B50: Defect ID (found before fix) | F50: B01 | G50: B01 | H50: B01 | I50: B01

Sheet Function2
A2: Function Code | C2: =Functions!E12 -> Function2 | F2: Function Name | L2: =Functions!D12 -> calculateDiscount(double subtotal)
A3: Created By | C3: Nam (DE200481) | F3: Executed By | L3: Nam (DE200481)
A4: Lines of code | C4: 15 | F4: Lack of test cases | L4: =IF(Functions!E6<>"N/A",SUM(C4*Functions!E6/1000,-O7),"N/A") -> -11.5
A5: Test requirement | C5: 0% (<1,000), 5% (1,000-<5,000), 10% (5,000-<10,000), 15% (>=10,000); negative subtotal throws IAE
A6: Passed | C6: Failed | F6: Untested | L6: N/A/B | O6: Total Test Cases
A7: =COUNTIF(F48:HQ48,"P") -> 13 | C7: =COUNTIF(F48:HQ48,"F") -> 0 | F7: =SUM(O7,-A7,-C7) -> 0 | L7: =COUNTIF(E47:HQ47,"N") -> 4 | M7: =COUNTIF(E47:HQ47,"A") -> 2 | N7: =COUNTIF(E47:HQ47,"B") -> 7 | O7: =COUNTA(F9:HT9) -> 13
F9: D01 | G9: D02 | H9: D03 | I9: D04 | J9: D05 | K9: D06 | L9: D07 | M9: D08 | N9: D09 | O9: D10 | P9: D11 | Q9: D12 | R9: D13
A10: Condition | B10: Precondition
D11: SalesService object created (new SalesService()); JDK 17, JUnit 5
B12: subtotal
D13: 0 | F13: O
D14: 500 | G14: O
D15: 999.99 | H15: O
D16: 1000 | I16: O
D17: 2500 | J17: O
D18: 4999.99 | K18: O
D19: 5000 | L19: O
D20: 7500 | M20: O
D21: 9999.99 | N21: O
D22: 10000 | O22: O
D23: 20000 | P23: O
D24: -1 | Q24: O
D25: -0.01 | R25: O
A26: Confirm | B26: Return
D27: 0 | F27: O | G27: O | H27: O
D28: 50 | I28: O
D29: 125 | J29: O
D30: 249.9995 | K30: O
D31: 500 | L31: O
D32: 750 | M32: O
D33: 999.999 | N33: O
D34: 1500 | O34: O
D35: 3000 | P35: O
B36: Exception
D37: IllegalArgumentException | Q37: O | R37: O
B38: Log message
D39: "Subtotal cannot be negative" | Q39: O | R39: O
A47: Result | B47: Type(N : Normal, A : Abnormal, B : Boundary) | F47: B | G47: N | H47: B | I47: B | J47: N | K47: B | L47: B | M47: N | N47: B | O47: B | P47: N | Q47: A | R47: A
B48: Passed/Failed | F48: P | G48: P | H48: P | I48: P | J48: P | K48: P | L48: P | M48: P | N48: P | O48: P | P48: P | Q48: P | R48: P
B49: Executed Date | F49: 46300 | G49: 46300 | H49: 46300 | I49: 46300 | J49: 46300 | K49: 46300 | L49: 46300 | M49: 46300 | N49: 46300 | O49: 46300 | P49: 46300 | Q49: 46300 | R49: 46300
...

Sheet Function3
A2: Function Code | C2: =Functions!E13 -> Function3 | F2: Function Name | L2: =Functions!D13 -> calculateShippingFee(double subtotal)
A3: Created By | C3: Nam (DE200481) | F3: Executed By | L3: Nam (DE200481)
A4: Lines of code | C4: 10 | F4: Lack of test cases | L4: =IF(Functions!E6<>"N/A",SUM(C4*Functions!E6/1000,-O7),"N/A") -> -6
A5: Test requirement | C5: 50 if subtotal < 2,000, otherwise 0; negative subtotal throws IAE
A6: Passed | C6: Failed | F6: Untested | L6: N/A/B | O6: Total Test Cases
A7: =COUNTIF(F48:HQ48,"P") -> 7 | C7: =COUNTIF(F48:HQ48,"F") -> 0 | F7: =SUM(O7,-A7,-C7) -> 0 | L7: =COUNTIF(E47:HQ47,"N") -> 2 | M7: =COUNTIF(E47:HQ47,"A") -> 1 | N7: =COUNTIF(E47:HQ47,"B") -> 4 | O7: =COUNTA(F9:HT9) -> 7
F9: H01 | G9: H02 | H9: H03 | I9: H04 | J9: H05 | K9: H06 | L9: H07
A10: Condition | B10: Precondition
D11: SalesService object created (new SalesService()); JDK 17, JUnit 5
B12: subtotal
D13: 0 | F13: O
D14: 500 | G14: O
D15: 1999.99 | H15: O
D16: 2000 | I16: O
D17: 2000.01 | J17: O
D18: 5000 | K18: O
D19: -1 | L19: O
A20: Confirm | B20: Return
D21: 50 | F21: O | G21: O | H21: O
D22: 0 | I22: O | J22: O | K22: O
B23: Exception
D24: IllegalArgumentException | L24: O
B25: Log message
D26: "Subtotal cannot be negative" | L26: O
A47: Result | B47: Type(N : Normal, A : Abnormal, B : Boundary) | F47: B | G47: N | H47: B | I47: B | J47: B | K47: N | L47: A
B48: Passed/Failed | F48: P | G48: P | H48: P | I48: P | J48: P | K48: P | L48: P
B49: Executed Date | F49: 46300 | G49: 46300 | H49: 46300 | I49: 46300 | J49: 46300 | K49: 46300 | L49: 46300
B50: Defect ID (found before fix) | I50: B03

Sheet Function4
A2: Function Code | C2: =Functions!E14 -> Function4 | F2: Function Name | L2: =Functions!D14 -> calculateTotal(Product p)
A3: Created By | C3: Nam (DE200481) | F3: Executed By | L3: Nam (DE200481)
A4: Lines of code | C4: 6 | F4: Lack of test cases | L4: =IF(Functions!E6<>"N/A",SUM(C4*Functions!E6/1000,-O7),"N/A") -> -6.4
A5: Test requirement | C5: Total = Subtotal - Discount + Shipping; null product throws IAE
A6: Passed | C6: Failed | F6: Untested | L6: N/A/B | O6: Total Test Cases
A7: =COUNTIF(F48:HQ48,"P") -> 7 | C7: =COUNTIF(F48:HQ48,"F") -> 0 | F7: =SUM(O7,-A7,-C7) -> 0 | L7: =COUNTIF(E47:HQ47,"N") -> 3 | M7: =COUNTIF(E47:HQ47,"A") -> 1 | N7: =COUNTIF(E47:HQ47,"B") -> 3 | O7: =COUNTA(F9:HT9) -> 7
F9: T01 | G9: T02 | H9: T03 | I9: T04 | J9: T05 | K9: T06 | L9: T07
A10: Condition | B10: Precondition
D11: SalesService object created (new SalesService()); JDK 17, JUnit 5
B12: price
D13: 500 | F13: O | G13: O
D14: 1000 | H14: O | I14: O
D15: 2000 | J15: O
D16: 3000 | K16: O
B17: quantity
D18: 1 | F18: O
D19: 3 | G19: O
D20: 2 | H20: O
D21: 5 | I21: O | J21: O
D22: 10 | K22: O
B23: Product
D24: null | L24: O
A25: Confirm | B25: Return
D26: 550 | F26: O
D27: 1475 | G27: O
D28: 1900 | H28: O
D29: 4500 | I29: O
D30: 8500 | J30: O
D31: 25500 | K31: O
B32: Exception
D33: IllegalArgumentException | L33: O
B34: Log message
D35: "Product cannot be null" | L35: O
A47: Result | B47: Type(N : Normal, A : Abnormal, B : Boundary) | F47: N | G47: N | H47: B | I47: B | J47: B | K47: N | L47: A
B48: Passed/Failed | F48: P | G48: P | H48: P | I48: P | J48: P | K48: P | L48: P
B49: Executed Date | F49: 46300 | G49: 46300 | H49: 46300 | I49: 46300 | J49: 46300 | K49: 46300 | L49: 46300
B50: Defect ID (found before fix) | F50: B01 | G50: B01, B04 | H50: B01, B04 | I50: B01, B04 | J50: B01, B04 | K50: B01, B04

Sheet Function5
A2: Function Code | C2: =Functions!E15 -> Function5 | F2: Function Name | L2: =Functions!D15 -> classifyCustomer(double total)
A3: Created By | C3: Nam (DE200481) | F3: Executed By | L3: Nam (DE200481)
A4: Lines of code | C4: 11 | F4: Lack of test cases | L4: =IF(Functions!E6<>"N/A",SUM(C4*Functions!E6/1000,-O7),"N/A") -> -8.9
A5: Test requirement | C5: REGULAR (<1,000), SILVER (1,000-<5,000), GOLD (5,000-<10,000), VIP (>=10,000)
A6: Passed | C6: Failed | F6: Untested | L6: N/A/B | O6: Total Test Cases
A7: =COUNTIF(F48:HQ48,"P") -> 10 | C7: =COUNTIF(F48:HQ48,"F") -> 0 | F7: =SUM(O7,-A7,-C7) -> 0 | L7: =COUNTIF(E47:HQ47,"N") -> 4 | M7: =COUNTIF(E47:HQ47,"A") -> 0 | N7: =COUNTIF(E47:HQ47,"B") -> 6 | O7: =COUNTA(F9:HT9) -> 10
F9: C01 | G9: C02 | H9: C03 | I9: C04 | J9: C05 | K9: C06 | L9: C07 | M9: C08 | N9: C09 | O9: C10
A10: Condition | B10: Precondition
D11: SalesService object created (new SalesService()); JDK 17, JUnit 5
B12: total
D13: 500 | F13: O
D14: 999.99 | G14: O
D15: 1000 | H15: O
D16: 3000 | I16: O
D17: 4999.99 | J17: O
D18: 5000 | K18: O
D19: 7500 | L19: O
D20: 9999.99 | M20: O
D21: 10000 | N21: O
D22: 25000 | O22: O
A23: Confirm | B23: Return
D24: REGULAR | F24: O | G24: O
D25: SILVER | H25: O | I25: O | J25: O
D26: GOLD | K26: O | L26: O | M26: O
D27: VIP | N27: O | O27: O
B28: Exception
D29: (none)
B30: Log message
D31: (none)
A47: Result | B47: Type(N : Normal, A : Abnormal, B : Boundary) | F47: N | G47: B | H47: B | I47: N | J47: B | K47: B | L47: N | M47: B | N47: B | O47: N
B48: Passed/Failed | F48: P | G48: P | H48: P | I48: P | J48: P | K48: P | L48: P | M48: P | N48: P | O48: P
B49: Executed Date | F49: 46300 | G49: 46300 | H49: 46300 | I49: 46300 | J49: 46300 | K49: 46300 | L49: 46300 | M49: 46300 | N49: 46300 | O49: 46300
B50: Defect ID (found before fix) | N50: B05

Sheet Example
A2: Function Code | C2: =Functions!E11 -> Function1 | F2: Function Name | L2: =Functions!D11 -> calculateSubtotal(Product p)
A3: Created By | C3: <Developer Name> | F3: Executed By
A4: Lines of code | C4: 100 | F4: Lack of test cases | L4: =IF(Functions!E6<>"N/A",SUM(C4*Functions!E6/1000,-O7),"N/A") -> -5
A5: Test requirement | C5: <Brief description about requirements which are tested in this function>
A6: Passed | C6: Failed | F6: Untested | L6: N/A/B | O6: Total Test Cases
A7: =COUNTIF(F47:HQ47,"P") -> 0 | C7: =COUNTIF(F47:HQ47,"F") -> 0 | F7: =SUM(O7,-A7,-C7) -> 15 | L7: =COUNTIF(E46:HQ46,"N") -> 0 | M7: =COUNTIF(E46:HQ46,"A") -> 0 | N7: =COUNTIF(E46:HQ46,"B") -> 0 | O7: =COUNTA(E9:HT9) -> 15
F9: UTCID01 | G9: UTCID02 | H9: UTCID02 | I9: UTCID02 | J9: UTCID02 | K9: UTCID02 | L9: UTCID07 | M9: UTCID08 | N9: UTCID09 | O9: UTCID10 | P9: UTCID11 | Q9: UTCID12 | R9: UTCID13 | S9: UTCID14 | T9: UTCID15
A10: Condition | B10: Precondition
B14: a
D15: -2 | F15: O
D16: -1 | L16: O
D17: 0 | G17: O | H17: O | I17: O
D18: 1 | J18: O | K18: O
B19: b
D20: 0 | G20: O | H20: O
D21: -2 | J21: O | K21: O | L21: O
D22: 2 | I22: O
B23: c
D24: 0 | G24: O
D25: 1 | H25: O | I25: O | J25: O
D26: 3 | L26: O
D27: 5 | K27: O
A33: Confirm | B33: Return
B34: list
D35: null | F35: O | H35: O | K35: O
D36: size = 0 | G36: O
D37: {-1/2} | I37: O
D38: {1,1} | J38: O
D39: {1,-3} | L39: O
B40: Exception
B42: Log message
D43: "please input a>= -1" | F43: O
A45: Result | B45: Type(N : Normal, A : Abnormal, B : Boundary) | F45: A | G45: N | H45: N | I45: N | J45: N | K45: N | L45: B
B46: Passed/Failed
B47: Executed Date | F47: 39139 | G47: 39139 | H47: 39139 | I47: 39139 | J47: 39139 | K47: 39139 | L47: 39144
B48: Defect ID
